<mujoco>
	<body mocap="true" name="robot0:mocap" pos="0 0 0">
		<geom conaffinity="0" contype="0" pos="0 0 0" rgba="0 0.5 0 0.7" size="0.005 0.005 0.005" type="box"></geom>
		<geom conaffinity="0" contype="0" pos="0 0 0" rgba="0 0.5 0 0.1" size="1 0.005 0.005" type="box"></geom>
		<geom conaffinity="0" contype="0" pos="0 0 0" rgba="0 0.5 0 0.1" size="0.005 1 0.001" type="box"></geom>
		<geom conaffinity="0" contype="0" pos="0 0 0" rgba="0 0.5 0 0.1" size="0.005 0.005 1" type="box"></geom>
	</body>
	<body childclass="robot0:fetch" name="robot0:base_link" pos="0 0 0">
		<joint armature="0.0001" axis="1 0 0" damping="1e+11" name="robot0:slide0" pos="0 0 0" type="slide"></joint>
		<joint armature="0.0001" axis="0 1 0" damping="1e+11" name="robot0:slide1" pos="0 0 0" type="slide"></joint>
		<joint armature="0.0001" axis="0 0 1" damping="1e+11" name="robot0:slide2" pos="0 0 0" type="slide"></joint>
		<inertial diaginertia="1.2869 1.2236 0.9868" mass="70.1294" pos="-0.0036 0 0.0014" quat="0.7605 -0.0133 -0.0061 0.6491"></inertial>
		<geom mesh="robot0:base_link" name="robot0:base_link" material="robot0:base_mat" class="robot0:grey"></geom>
		<body name="robot0:head_camera_link" pos="0.055 0 0.0225">
			<inertial diaginertia="0 0 0" mass="0" pos="0.055 0 0.0225"></inertial>
			<body name="robot0:head_camera_rgb_frame" pos="0 0.02 0">
				<inertial diaginertia="0 0 0" mass="0" pos="0 0.02 0"></inertial>
				<body name="robot0:head_camera_rgb_optical_frame" pos="0 0 0" quat="0.5 -0.5 0.5 -0.5">
					<inertial diaginertia="0 0 0" mass="0" pos="0 0 0" quat="0.5 -0.5 0.5 -0.5"></inertial>
					<camera euler="3.1415 0 0" fovy="50" name="head_camera_rgb" pos="0 0 0"></camera>
				</body>
			</body>
			<body name="robot0:head_camera_depth_frame" pos="0 0.045 0">
				<inertial diaginertia="0 0 0" mass="0" pos="0 0.045 0"></inertial>
				<body name="robot0:head_camera_depth_optical_frame" pos="0 0 0" quat="0.5 -0.5 0.5 -0.5">
					<inertial diaginertia="0 0 0" mass="0" pos="0 0 0" quat="0.5 -0.5 0.5 -0.5"></inertial>
				</body>
			</body>
			<body name="robot0:link_1" pos="-0.055 0 0.0775" quat="0 -1 0 0">
				<inertial pos="-0.00396819 -1.06212e-07 -0.0750652" quat="0 0 0 0.707" mass="3.99039" diaginertia="0.0170615 0.0164142 0.0152359"></inertial>
				<joint axis="0 0 -1" limited="true" name="robot0:link_1_joint" range="-1.5707 1.5707"></joint>
				<geom mesh="robot0:link_1" name="robot0:link_1" material="robot0:arm_mat" class="robot0:grey"></geom>
				<body name="robot0:link_2" pos="-0.1 0 -0.0765" quat="0.499998 -0.5 0.500002 -0.5">
					<inertial pos="-8.3323e-07 0.107028 -0.0983468" quat="0.713797 0.700352 -4.70168e-05 4.79194e-05" mass="9.58894" diaginertia="0.130066 0.128883 0.0397389"></inertial>
					<joint axis="0 0 -1" limited="true" name="robot0:link_2_joint" range="-0.785 0.785"></joint>
					<geom mesh="robot0:link_2" name="robot0:link_2" material="robot0:arm_mat" class="robot0:grey"></geom>
					<body name="robot0:link_3" pos="0 0.294 -0.1" quat="0.499998 0.5 0.5 -0.500002">
                    	<inertial pos="-0.00165319 -8.12072e-06 -0.186972" quat="0.705206 0.00670436 0.00674079 0.708939" mass="9.58894" diaginertia="0.130066 0.128883 0.0397389"></inertial>
						<joint axis="0 0 -1" limited="true" name="robot0:link_3_joint" range="-0.785 0.785"></joint>
						<geom mesh="robot0:link_3" name="robot0:link_3" material="robot0:arm_mat" class="robot0:grey"></geom>
						<body name="robot0:link_4" pos="-0.099999 -0.00054139 -0.294" quat="0.498646 0.498648 0.50135 0.501348">
                        	<inertial pos="8.29222e-07 -0.107028 -0.0983468" quat="0.700352 0.713797 4.78466e-05 -4.69454e-05" mass="9.58894" diaginertia="0.130066 0.128883 0.0397389" />
							<joint axis="0 0 -1" limited="true" name="robot0:link_4_joint" range="0 1.57"></joint>
							<geom mesh="robot0:link_4" name="robot0:link_4" material="robot0:arm_mat" class="robot0:grey"></geom>
							<body name="robot0:link_5" pos="0 -0.294 -0.1" quat="0.498648 -0.49865 -0.501346 -0.501348">
                            	<inertial pos="0.00165288 3.26101e-05 -0.186972" quat="0.699937 -0.00665423 -0.00679021 0.714141" mass="9.58894" diaginertia="0.130066 0.128883 0.0397389" />
								<joint axis="0 0 -1" limited="false" name="robot0:link_5_joint"></joint>
								<geom mesh="robot0:link_5" name="robot0:link_5" material="robot0:arm_mat" class="robot0:grey"></geom>
								<body name="robot0:link_6" pos="0.09998 0.0020221 -0.294" quat="0.494923 -0.494925 -0.505026 0.505024">
                                	<inertial pos="-8.18395e-07 0.107028 -0.0983468" quat="0.713797 0.700352 -4.67556e-05 4.76532e-05" mass="9.58894" diaginertia="0.130066 0.128883 0.0397389" />
									<joint axis="0 0 -1" limited="true" name="robot0:link_6_joint" range="-2.16 2.16"></joint>
									<geom mesh="robot0:link_6" name="robot0:link_6" material="robot0:arm_mat" class="robot0:grey"></geom>
									<body name="robot0:link_7" pos="0 0.294 -0.1" quat="0.494925 0.494926 0.505023 -0.505024">
                                    	<inertial pos="0 0 -0.075" quat="0.5 0.5 -0.5 0.5" mass="4.71239" diaginertia="0.0235619 0.0206167 0.0206167" />
										<joint axis="0 0 -1" limited="false" name="robot0:link_7_joint"></joint>
										<geom mesh="robot0:link_7" name="robot0:link_7" material="robot0:arm_mat" class="robot0:grey"></geom>
										<body name="robot0:gripper_camera_link" pos="0 0 -0.25">
											<body name="robot0:gripper_camera_rgb_frame" pos="0 0.02 0">
												<body name="robot0:gripper_camera_rgb_optical_frame" pos="0 0 0" quat="0.5 -0.5 0.5 -0.5">
													<camera euler="3.1415 0 0" fovy="50" name="gripper_camera_rgb" pos="0 0 0"></camera>
												</body>
											</body>
											<body name="robot0:gripper_camera_depth_frame" pos="0 0.045 0">
												<body name="robot0:gripper_camera_depth_optical_frame" pos="0 0 0" quat="0.5 -0.5 0.5 -0.5">
												</body>
											</body>
										</body>
										<body childclass="robot0:fetchGripper" name="robot0:r_gripper_finger_link" quat="0.707 0.707 0 0" pos="-0.1 0.09 -0.25" >
											<inertial diaginertia="0.1 0.1 0.1" mass="4" pos="-0.01 0 0"></inertial>
											<joint axis="0 -1 0" name="robot0:r_end_effector_joint" range="0 0.01"></joint>
											<geom type="mesh" mesh="robot0:gripper" material="robot0:gripper_mat" condim="4" friction="1 0.05 0.01" ></geom>
										</body>
										<body childclass="robot0:fetchGripper" name="robot0:l_gripper_finger_link" quat="0.707 -0.707 0 0" pos="-0.1 -0.1 -0.15" >
											<inertial diaginertia="0.1 0.1 0.1" mass="4" pos="-0.01 0 0"></inertial>
											<joint axis="0 -1 0" name="robot0:l_end_effector_joint" range="0 0.01"></joint>
											<geom type="mesh" mesh="robot0:gripper" material="robot0:gripper_mat" condim="4" friction="1 0.05 0.01" ></geom>
										</body>
											<site name="robot0:grip" pos="0.02 0 0" rgba="0 0 0 0" size="0.02 0.02 0.02"></site>
									</body>
								</body>
							</body>
						</body>
					</body>
				</body>
			</body>
		</body>

		<body name="robot0:external_camera_body_0" pos="0 0 0">
			<camera euler="0 0.75 1.57" fovy="43.3" name="external_camera_0" pos="1.3 0 1.2"></camera>
		</body>
	</body>
</mujoco>
